Traceback (most recent call last):
  File "C:\Users\pascaie\Documents\python_test_private\AutomateTasks\10_debugging\tracebackHandling.py", line 7, in <module>
    raise Exception('This is an error message')
Exception: This is an error message
